Workbook

Sheet Summary
B2: ALL PERMITS - Authorization and Pumping Summary | I2: External Data | M2: CAP : | N2: 572000
B3: Year | C3: CPM | D3: All Permits | I3: Total Annual | J3: Permitted | M3: ACTUAL : | N3: 571599.5
C4: SA / UV | D4: Permitted | E4: After CPM | F4: Pumped | G4: Un-Pumped | I4: Recharge | J4: Overpump | M4: RESIDUAL : | N4: =N2-N3 -> 400.5
B5: 2008 | C5: 1.64% / 0% | D5: =D26+H26+D47+H47 -> 571599.5 | E5: =E26+I26+E47+I47 -> 564097.08 | F5: =F26+J26+F47+J47 -> 408178 | G5: =G26+K26+G47+K47 -> 155919.08 | I5: =Recharge!C11 -> 212900 | J5: 862.8459 | K5: =1-((E5-J5)/E5) -> 0.0015296053
B6: 2009 | C6: 11.8% / 0% | D6: =D27+H27+D48+H48 -> 571599.5 | E6: =E27+I27+E48+I48 -> 514802.57 | F6: =F27+J27+F48+J48 -> 377255 | G6: =G27+K27+G48+K48 -> 137547.57 | I6: =Recharge!C12 -> 211000 | J6: 1119.374 | K6: =1-((E6-J6)/E6) -> 0.0021743753
B7: 2010 | C7: 0% / 0% | D7: =D28+H28+D49+H49 -> 571599.5 | E7: =E28+I28+E49+I49 -> 571599.5 | F7: =F28+J28+F49+J49 -> 354081 | G7: =G28+K28+G49+K49 -> 217518.5 | I7: =Recharge!C13 -> 813500 | J7: 68.861 | K7: =1-((E7-J7)/E7) -> 0.00012047071
B8: 2011 | C8: 19.2% / 2.60% | D8: =D29+H29+D50+H50 -> 571599.5 | E8: =E29+I29+E50+I50 -> 476851.82 | F8: =F29+J29+F50+J50 -> 408628 | G8: =G29+K29+G50+K50 -> 68223.816 | I8: =Recharge!C14 -> 112000 | J8: 1483.129 | K8: =1-((E8-J8)/E8) -> 0.0031102513
B9: 2012 | C9: 22.4% / 17.40% | D9: =D30+H30+D51+H51 -> 571599.5 | E9: =E30+I30+E51+I51 -> 448136.4 | F9: =F30+J30+F51+J51 -> 370993 | G9: =G30+K30+G51+K51 -> 77143.401 | I9: =Recharge!C15 -> 313500 | J9: 688.982 | K9: =1-((E9-J9)/E9) -> 0.0015374382
B10: 2013 | C10: 28.9% / 41.80% | D10: =D31+H31+D52+H52 -> 571599.5 | E10: =E31+I31+E52+I52 -> 394826.11 | F10: =F31+J31+F52+J52 -> 336634 | G10: =G31+K31+G52+K52 -> 58192.107 | I10: =Recharge!C16 -> 182700 | J10: 1201.631 | K10: =1-((E10-J10)/E10) -> 0.0030434436
B11: 2014 | C11: 35.0% / 44.0% | D11: =D32+H32+D53+H53 -> 571599.5 | E11: =E32+I32+E53+I53 -> 363534.97 | F11: =F32+J32+F53+J53 -> 312948.61 | G11: =G32+K32+G53+K53 -> 50586.358 | I11: =Recharge!C17 -> 107200 | J11: 416.794 | K11: =1-((E11-J11)/E11) -> 0.0011465032
B12: 2015 | C12: 19.7% / 20.4% | D12: =D33+H33+D54+H54 -> 571599.5 | E12: =E33+I33+E54+I54 -> 425788.34 | F12: =F33+J33+F54+J54 -> 305507.36 | G12: =G33+K33+G54+K54 -> 120280.98 | I12: =Recharge!C18 -> 1358300 | J12: 590.35332 | K12: =1-((E12-J12)/E12) -> 0.0013864948
B13: 2016 | C13: 0% / 0% | D13: =D34+H34+D55+H55 -> 571599.5 | E13: =E34+I34+E55+I55 -> 571599.5 | F13: =F34+J34+F55+J55 -> 305994.09 | G13: =G34+K34+G55+K55 -> 265605.41 | I13: =Recharge!C19 -> 1221100 | J13: 325.063 | K13: =1-((E13-J13)/E13) -> 0.00056869014
B14: 2017 | C14: 3.2% / 0% | D14: =D35+H35+D56+H56 -> 571599 | E14: =E35+I35+E56+I56 -> 555471.7 | F14: =F35+J35+F56+J56 -> 359851.97 | G14: =G35+K35+G56+K56 -> 195619.73 | I14: =Recharge!C20 -> 487000 | J14: 417.025 | K14: =1-((E14-J14)/E14) -> 0.00075075831
B15: 2018 | C15: 8.7% / 0% | D15: =D36+H36+D57+H57 -> 571599 | E15: =E36+I36+E57+I57 -> 531073 | F15: =F36+J36+F57+J57 -> 351140 | G15: =G36+K36+G57+K57 -> 179933 | I15: =Recharge!C21 -> 1100000 | J15: 1250.7229 | K15: =1-((E15-J15)/E15) -> 0.0023550867
B16: 2019 | C16: 0% / 0% | D16: =D37+H37+D58+H58 -> 571599.5 | E16: =E37+I37+E58+I58 -> 571599.5 | F16: =F37+J37+F58+J58 -> 339019.63 | G16: =G37+K37+G58+K58 -> 232579.87 | I16: =Recharge!C22 -> 492000 | J16: 361.5 | K16: =1-((E16-J16)/E16) -> 0.00063243582
... B20: 2023 | C20: 35.8% / 17.3% | D20: =D41+H41+D62+H62 -> 571599.5 | E20: =E41+I41+E62+I62 -> 362801.14 | F20: =F41+J41+F62+J62 -> 299986.58 | G20: =G41+K41+G62+K62 -> 62814.564 | I20: =Recharge!C26 -> 147000 | J20: 2768.315 | K20: =1-((E20-J20)/E20) -> 0.0076303921
B23: SAN ANTONIO POOL - Authorization and Pumping Summary
B24: Year | C24: CPM | D24: Municipal & Industrial | H24: Irrigation | M24: San Antonio Pool
D25: Permitted | E25: After CPM | F25: Pumped | G25: Un-Pumped | H25: Permitted | I25: After CPM | J25: Pumped | K25: Un-Pumped | M25: Permitted | N25: Authorized | O25: Pumped
B26: 2008 | C26: 0.0164 | D26: =Permitted!B5 -> 372670.7 | E26: =Permitted!C5 -> 366711.18 | F26: =Pumped!O25 -> 290576 | G26: =E26-F26 -> 76135.184 | H26: =Permitted!D5 -> 96489.03 | I26: =Permitted!E5 -> 94946.129 | J26: =Pumped!P25 -> 48993 | K26: =I26-J26 -> 45953.129 | M26: =D26+H26 -> 469159.73 | N26: =E26+I26 -> 461657.31 | O26: =F26+J26 -> 339569
B27: 2009 | C27: 0.118 | D27: =Permitted!B6 -> 395184.2 | E27: =Permitted!C6 -> 348584.67 | F27: =Pumped!O26 -> 263465 | G27: =E27-F27 -> 85119.666 | H27: =Permitted!D6 -> 86495.405 | I27: =Permitted!E6 -> 76298.008 | J27: =Pumped!P26 -> 50072 | K27: =I27-J27 -> 26226.008 | M27: =D27+H27 -> 481679.61 | N27: =E27+I27 -> 424882.67 | O27: =F27+J27 -> 313537
B28: 2010 | C28: 0 | D28: =Permitted!B7 -> 393080.05 | E28: =Permitted!C7 -> 393080.05 | F28: =Pumped!O27 -> 277297 | G28: =E28-F28 -> 115783.05 | H28: =Permitted!D7 -> 90729.161 | I28: =Permitted!E7 -> 90729.161 | J28: =Pumped!P27 -> 34572 | K28: =I28-J28 -> 56157.161 | M28: =D28+H28 -> 483809.21 | N28: =E28+I28 -> 483809.21 | O28: =F28+J28 -> 311869
B29: 2011 | C29: 0.192 | D29: =Permitted!B8 -> 391712.39 | E29: =Permitted!C8 -> 316553.11 | F29: =Pumped!O28 -> 278710 | G29: =E29-F29 -> 37843.108 | H29: =Permitted!D8 -> 89926.544 | I29: =Permitted!E8 -> 72676.405 | J29: =Pumped!P28 -> 56734 | K29: =I29-J29 -> 15942.405 | M29: =D29+H29 -> 481638.93 | N29: =E29+I29 -> 389229.51 | O29: =F29+J29 -> 335444
B30: 2012 | C30: 0.224 | D30: =Permitted!B9 -> 395184.2 | E30: =Permitted!C9 -> 306722.12 | F30: =Pumped!O29 -> 275939 | G30: =E30-F30 -> 30783.121 | H30: =Permitted!D9 -> 86495.405 | I30: =Permitted!E9 -> 67135.249 | J30: =Pumped!P29 -> 41393 | K30: =I30-J30 -> 25742.249 | M30: =D30+H30 -> 481679.61 | N30: =E30+I30 -> 373857.37 | O30: =F30+J30 -> 317332
B31: 2013 | C31: 0.289 | D31: =Permitted!B10 -> 390218.9 | E31: =Permitted!C10 -> 277526.36 | F31: =Pumped!O30 -> 256328 | G31: =E31-F31 -> 21198.356 | H31: =Permitted!D10 -> 90667.546 | I31: =Permitted!E10 -> 64491.786 | J31: =Pumped!P30 -> 39382 | K31: =I31-J31 -> 25109.786 | M31: =D31+H31 -> 480886.45 | N31: =E31+I31 -> 342018.14 | O31: =F31+J31 -> 295710
B32: 2014 | C32: 0.35 | D32: =Permitted!B11 -> 401030.07 | E32: =Permitted!C11 -> 260761.15 | F32: =Pumped!O31 -> 233850.99 | G32: =E32-F32 -> 26910.162 | H32: =Permitted!D11 -> 79692.378 | I32: =Permitted!E11 -> 51839.197 | J32: =Pumped!P31 -> 40231.253 | K32: =I32-J32 -> 11607.944 | M32: =D32+H32 -> 480722.45 | N32: =E32+I32 -> 312600.35 | O32: =F32+J32 -> 274082.24
B33: 2015 | C33: 0.197 | D33: =Permitted!B12 -> 405065.8 | E33: =Permitted!C12 -> 325316.44 | F33: =Pumped!O32 -> 260459.48 | G33: =E33-F33 -> 64856.96 | H33: =Permitted!D12 -> 105419.77 | I33: =Permitted!E12 -> 51816.759 | J33: =Pumped!P32 -> 22677.752 | K33: =I33-J33 -> 29139.007 | M33: =D33+H33 -> 510485.58 | N33: =E33+I33 -> 377133.2 | O33: =F33+J33 -> 283137.23
B34: 2016 | C34: 0 | D34: =Permitted!B13 -> 418149.01 | E34: =Permitted!C13 -> 418149.01 | F34: =Pumped!O33 -> 248209.24 | G34: =E34-F34 -> 169939.78 | H34: =Permitted!D13 -> 76714.127 | I34: =Permitted!E13 -> 76714.127 | J34: =Pumped!P33 -> 25857.167 | K34: =I34-J34 -> 50856.96 | M34: =D34+H34 -> 494863.14 | N34: =E34+I34 -> 494863.14 | O34: =F34+J34 -> 274066.4
B35: 2017 | C35: 0.034 | D35: =Permitted!B14 -> 415744 | E35: =Permitted!C14 -> 401608.7 | F35: =Pumped!O34 -> 282422.28 | G35: =E35-F35 -> 119186.42 | H35: =Permitted!D14 -> 77149 | I35: =Permitted!E14 -> 75157 | J35: =Pumped!P34 -> 38585.229 | K35: =I35-J35 -> 36571.771 | M35: =D35+H35 -> 492893 | N35: =E35+I35 -> 476765.7 | O35: =F35+J35 -> 321007.51
B36: 2018 | C36: 0.087 | D36: =Permitted!B15 -> 414919 | E36: =Permitted!C15 -> 378598 | F36: =Pumped!O35 -> 263806 | G36: =E36-F36 -> 114792 | H36: =Permitted!D15 -> 78325 | I36: =Permitted!E15 -> 74120 | J36: =Pumped!P35 -> 37447 | K36: =I36-J36 -> 36673 | M36: =D36+H36 -> 493244 | N36: =E36+I36 -> 452718 | O36: =F36+J36 -> 301253
B37: 2019 | C37: 0 | D37: =Permitted!B16 -> 392611.01 | E37: =Permitted!C16 -> 392611.01 | F37: =Pumped!O36 -> 262224.18 | G37: =E37-F37 -> 130386.83 | H37: =Permitted!D16 -> 87073.653 | I37: =Permitted!E16 -> 87073.653 | J37: =Pumped!P36 -> 34851.875 | K37: =I37-J37 -> 52221.778 | M37: =D37+H37 -> 479684.66 | N37: =E37+I37 -> 479684.66 | O37: =F37+J37 -> 297076.05
... B41: 2023 | C41: 0.358 | D41: =Permitted!B20 -> 380907.19 | E41: =Permitted!C20 -> 244577.58 | F41: =Pumped!O40 -> 227096.91 | G41: =E41-F41 -> 17480.676 | H41: =Permitted!D20 -> 87107.947 | I41: =Permitted!E20 -> 52159.448 | J41: =Pumped!P40 -> 31368.401 | K41: =I41-J41 -> 20791.047 | M41: =D41+H41 -> 468015.13 | N41: =E41+I41 -> 296737.03 | O41: =F41+J41 -> 258465.31
B44: UVALDE POOL - Authorization and Pumping Summary
B45: Year | C45: CPM | D45: Municipal & Industrial | H45: Irrigation | M45: Uvalde Pool
D46: Permitted | E46: After CPM | F46: Pumped | G46: Un-Pumped | H46: Permitted | I46: After CPM | J46: Pumped | K46: Un-Pumped | M46: Permitted | N46: Authorized | O46: Pumped
B47: 2008 | C47: 0 | D47: =Permitted!F5 -> 6497.135 | E47: =Permitted!G5 -> 6497.135 | F47: =Pumped!O3 -> 4894 | G47: =E47-F47 -> 1603.135 | H47: =Permitted!H5 -> 95942.632 | I47: =Permitted!I5 -> 95942.632 | J47: =Pumped!P3 -> 63715 | K47: =I47-J47 -> 32227.632 | M47: =D47+H47 -> 102439.77 | N47: =E47+I47 -> 102439.77 | O47: =F47+J47 -> 68609
B48: 2009 | C48: 0 | D48: =Permitted!F6 -> 6852.02 | E48: =Permitted!G6 -> 6852.02 | F48: =Pumped!O4 -> 4904 | G48: =E48-F48 -> 1948.02 | H48: =Permitted!H6 -> 83067.871 | I48: =Permitted!I6 -> 83067.871 | J48: =Pumped!P4 -> 58814 | K48: =I48-J48 -> 24253.871 | M48: =D48+H48 -> 89919.891 | N48: =E48+I48 -> 89919.891 | O48: =F48+J48 -> 63718
B49: 2010 | C49: 0 | D49: =Permitted!F7 -> 6451.488 | E49: =Permitted!G7 -> 6451.488 | F49: =Pumped!O5 -> 4094 | G49: =E49-F49 -> 2357.488 | H49: =Permitted!H7 -> 81338.797 | I49: =Permitted!I7 -> 81338.797 | J49: =Pumped!P5 -> 38118 | K49: =I49-J49 -> 43220.797 | M49: =D49+H49 -> 87790.285 | N49: =E49+I49 -> 87790.285 | O49: =F49+J49 -> 42212
B50: 2011 | C50: 0.026 | D50: =Permitted!F8 -> 6496.488 | E50: =Permitted!G8 -> 6327.886 | F50: =Pumped!O6 -> 5013 | G50: =E50-F50 -> 1314.886 | H50: =Permitted!H8 -> 83464.077 | I50: =Permitted!I8 -> 81294.417 | J50: =Pumped!P6 -> 68171 | K50: =I50-J50 -> 13123.417 | M50: =D50+H50 -> 89960.565 | N50: =E50+I50 -> 87622.303 | O50: =F50+J50 -> 73184
B51: 2012 | C51: 0.174 | D51: =Permitted!F9 -> 6852.02 | E51: =Permitted!G9 -> 5662.306 | F51: =Pumped!O7 -> 4498 | G51: =E51-F51 -> 1164.306 | H51: =Permitted!H9 -> 83067.871 | I51: =Permitted!I9 -> 68616.725 | J51: =Pumped!P7 -> 49163 | K51: =I51-J51 -> 19453.725 | M51: =D51+H51 -> 89919.891 | N51: =E51+I51 -> 74279.031 | O51: =F51+J51 -> 53661
...

Sheet Permitted
B2: San Antonio Pool | F2: Uvalde Pool
A3: Year | B3: M&I Permitted | C3: M&I CPM Authorized | D3: Irrigation Permitted | E3: Irrigation CPM Authorized | F3: M&I Permitted | G3: M&I CPM Authorized | H3: Irrigation Permitted | I3: Irrigation CPM Authorized
A5: 2008 | B5: 372670.7 | C5: 366711.18 | D5: 96489.03 | E5: 94946.129 | F5: 6497.135 | G5: 6497.135 | H5: 95942.632 | I5: 95942.632
A6: 2009 | B6: 395184.2 | C6: 348584.67 | D6: 86495.405 | E6: 76298.008 | F6: 6852.02 | G6: 6852.02 | H6: 83067.871 | I6: 83067.871
A7: 2010 | B7: 393080.05 | C7: 393080.05 | D7: 90729.161 | E7: 90729.161 | F7: 6451.488 | G7: 6451.488 | H7: 81338.797 | I7: 81338.797
A8: 2011 | B8: 391712.39 | C8: 316553.11 | D8: 89926.544 | E8: 72676.405 | F8: 6496.488 | G8: 6327.886 | H8: 83464.077 | I8: 81294.417
A9: 2012 | B9: 395184.2 | C9: 306722.12 | D9: 86495.405 | E9: 67135.249 | F9: 6852.02 | G9: 5662.306 | H9: 83067.871 | I9: 68616.725
A10: 2013 | B10: 390218.9 | C10: 277526.36 | D10: 90667.546 | E10: 64491.786 | F10: 8966.284 | G10: 5224.562 | H10: 81746.766 | I10: 47583.403
A11: 2014 | B11: 401030.07 | C11: 260761.15 | D11: 79692.378 | E11: 51839.197 | F11: 8978.945 | G11: 5062.82 | H11: 81898.103 | I11: 45871.8
A12: 2015 | B12: =362228.059+42837.743 -> 405065.8 | C12: =290886.191+34430.245 -> 325316.44 | D12: 105419.77 | E12: =84676.489-32859.73 -> 51816.759 | F12: =5806.503+517.556 -> 6324.059 | G12: =4623.535+413.974 -> 5037.509 | H12: 54789.864 | I12: 43617.637
A13: 2016 | B13: =378039.384+40109.63 -> 418149.01 | C13: =378039.384+40109.63 -> 418149.01 | D13: 76714.127 | E13: 76714.127 | F13: =4924.488+365.225 -> 5289.713 | G13: =4924.488+365.225 -> 5289.713 | H13: 71446.646 | I13: 71446.646
A14: 2017 | B14: =38846+376898 -> 415744 | C14: 401608.7 | D14: 77149 | E14: 75157 | F14: 5499 | G14: 5499 | H14: 73207 | I14: 73207
A15: 2018 | B15: =B37-F15 -> 414919 | C15: =C37-G15 -> 378598 | D15: =D37-H15 -> 78325 | E15: =E37-I15 -> 74120 | F15: 4566 | G15: 4566 | H15: 73789 | I15: 73789
A16: 2019 | B16: 392611.01 | C16: 392611.01 | D16: 87073.653 | E16: 87073.653 | F16: 4693.526 | G16: 4693.526 | H16: 87221.312 | I16: 87221.312
A17: 2020 | B17: 392607.4 | C17: 368082.87 | D17: 86778.165 | E17: 81508.439 | F17: 4227.005 | G17: 4227.005 | H17: 87986.934 | I17: 87986.934
A18: 2021 | B18: 388575.8 | C18: 366425.94 | D18: 89182.571 | E18: 84098.997 | F18: 3584.646 | G18: 3584.646 | H18: 90256.479 | I18: 90256.479
A19: 2022 | B19: 389698.7 | C19: 286133.59 | D19: 89874.641 | E19: 71253.549 | F19: 4136.248 | G19: 3916.737 | H19: 87889.908 | I19: 82252.661
A20: 2023 | B20: 380907.19 | C20: 244577.58 | D20: 87107.947 | E20: 52159.448 | F20: 4364.211 | G20: 3614.071 | H20: 99220.155 | I20: 62450.044
B24: TOTALS | F24: GRAND TOTAL
A25: Year | B25: M&I Permitted | C25: M&I CPM Authorized | D25: Irrigation Permitted | E25: Irrigation CPM Authorized | F25: Permitted | G25: Authorized
A27: 2008 | B27: =B5+F5 -> 379167.84 | C27: =C5+G5 -> 373208.32 | D27: =D5+H5 -> 192431.66 | E27: =E5+I5 -> 190888.76 | F27: =B27+D27 -> 571599.5 | G27: =C27+E27 -> 564097.08
A28: 2009 | B28: =B6+F6 -> 402036.22 | C28: =C6+G6 -> 355436.69 | D28: =D6+H6 -> 169563.28 | E28: =E6+I6 -> 159365.88 | F28: =B28+D28 -> 571599.5 | G28: =C28+E28 -> 514802.57
A29: 2010 | B29: =B7+F7 -> 399531.54 | C29: =C7+G7 -> 399531.54 | D29: =D7+H7 -> 172067.96 | E29: =E7+I7 -> 172067.96 | F29: =B29+D29 -> 571599.5 | G29: =C29+E29 -> 571599.5
A30: 2011 | B30: =B8+F8 -> 398208.88 | C30: =C8+G8 -> 322880.99 | D30: =D8+H8 -> 173390.62 | E30: =E8+I8 -> 153970.82 | F30: =B30+D30 -> 571599.5 | G30: =C30+E30 -> 476851.82
A31: 2012 | B31: =B9+F9 -> 402036.22 | C31: =C9+G9 -> 312384.43 | D31: =D9+H9 -> 169563.28 | E31: =E9+I9 -> 135751.97 | F31: =B31+D31 -> 571599.5 | G31: =C31+E31 -> 448136.4
A32: 2013 | B32: =B10+F10 -> 399185.19 | C32: =C10+G10 -> 282750.92 | D32: =D10+H10 -> 172414.31 | E32: =E10+I10 -> 112075.19 | F32: =B32+D32 -> 571599.5 | G32: =C32+E32 -> 394826.11
A33: 2014 | B33: =B11+F11 -> 410009.02 | C33: =C11+G11 -> 265823.97 | D33: =D11+H11 -> 161590.48 | E33: =E11+I11 -> 97710.997 | F33: =B33+D33 -> 571599.5 | G33: =C33+E33 -> 363534.97
A34: 2015 | B34: =B12+F12 -> 411389.86 | C34: =C12+G12 -> 330353.95 | D34: =D12+H12 -> 160209.64 | E34: =E12+I12 -> 95434.396 | F34: =B34+D34 -> 571599.5 | G34: =C34+E34 -> 425788.34
A35: 2016 | B35: =B13+F13 -> 423438.73 | C35: =C13+G13 -> 423438.73 | D35: =D13+H13 -> 148160.77 | E35: =E13+I13 -> 148160.77 | F35: =B35+D35 -> 571599.5 | G35: =C35+E35 -> 571599.5
A36: 2017 | B36: =B14+F14 -> 421243 | C36: =C14+G14 -> 407107.7 | D36: =D14+H14 -> 150356 | E36: =E14+I14 -> 148364 | F36: =B36+D36 -> 571599 | G36: =C36+E36 -> 555471.7
A37: 2018 | B37: 419485 | C37: 383164 | D37: 152114 | E37: 147909 | F37: =B37+D37 -> 571599 | G37: =C37+E37 -> 531073
A38: 2019 | B38: 479684.66 | C38: 479684.66 | D38: 91914.838 | E38: 91914.838 | F38: =B38+D38 -> 571599.5 | G38: =C38+E38 -> 571599.5
A39: 2020 | B39: =B17+F17 -> 396834.4 | C39: =C17+G17 -> 372309.88 | D39: =D17+H17 -> 174765.1 | E39: =E17+I17 -> 169495.37 | F39: =B39+D39 -> 571599.5 | G39: =C39+E39 -> 541805.25
A40: 2021 | B40: =B18+F18 -> 392160.45 | C40: =C18+G18 -> 370010.58 | D40: =D18+H18 -> 179439.05 | E40: =E18+I18 -> 174355.48 | F40: =B40+D40 -> 571599.5 | G40: =C40+E40 -> 544366.06
A41: 2022 | B41: =B19+F19 -> 393834.95 | C41: =C19+G19 -> 290050.33 | D41: =D19+H19 -> 177764.55 | E41: =E19+I19 -> 153506.21 | F41: =B41+D41 -> 571599.5 | G41: =C41+E41 -> 443556.54
A42: 2023 | B42: =B20+F20 -> 385271.4 | C42: =C20+G20 -> 248191.65 | D42: =D20+H20 -> 186328.1 | E42: =E20+I20 -> 114609.49 | F42: =B42+D42 -> 571599.5 | G42: =C42+E42 -> 362801.14

Sheet Pumped
B1: Mun | C1: Ind | D1: Irr | F1: M&I | G1: Irr | H1: TOTAL | K1: Mun | L1: Ind | M1: Irr | O1: M&I | P1: Irr | Q1: TOTAL
A2: Atascosa | J2: UVALDE POOL
A3: 2008 | B3: 0 | C3: 0 | D3: 1165 | F3: =B3+C3 -> 0 | G3: =D3 -> 1165 | H3: =F3+G3 -> 1165 | J3: 2008 | K3: =B135 -> 4768 | L3: =C135 -> 126 | M3: =D135 -> 63715 | O3: =K3+L3 -> 4894 | P3: =M3 -> 63715 | Q3: =O3+P3 -> 68609
A4: 2009 | B4: 0 | C4: 0 | D4: 1150 | F4: =B4+C4 -> 0 | G4: =D4 -> 1150 | H4: =F4+G4 -> 1150 | J4: 2009 | K4: =B136 -> 4797 | L4: =C136 -> 107 | M4: =D136 -> 58814 | O4: =K4+L4 -> 4904 | P4: =M4 -> 58814 | Q4: =O4+P4 -> 63718
A5: 2010 | B5: 0 | C5: 0 | D5: 709 | F5: =B5+C5 -> 0 | G5: =D5 -> 709 | H5: =F5+G5 -> 709 | J5: 2010 | K5: =B137 -> 3975 | L5: =C137 -> 119 | M5: =D137 -> 38118 | O5: =K5+L5 -> 4094 | P5: =M5 -> 38118 | Q5: =O5+P5 -> 42212
A6: 2011 | B6: 0 | C6: 0 | D6: 1233 | F6: =B6+C6 -> 0 | G6: =D6 -> 1233 | H6: =F6+G6 -> 1233 | J6: 2011 | K6: =B138 -> 4862 | L6: =C138 -> 151 | M6: =D138 -> 68171 | O6: =K6+L6 -> 5013 | P6: =M6 -> 68171 | Q6: =O6+P6 -> 73184
A7: 2012 | B7: 0 | C7: 0 | D7: 1259 | F7: =B7+C7 -> 0 | G7: =D7 -> 1259 | H7: =F7+G7 -> 1259 | J7: 2012 | K7: =B139 -> 4355 | L7: =C139 -> 143 | M7: =D139 -> 49163 | O7: =K7+L7 -> 4498 | P7: =M7 -> 49163 | Q7: =O7+P7 -> 53661
A8: 2013 | B8: 0 | C8: 0 | D8: 1208 | F8: =B8+C8 -> 0 | G8: =D8 -> 1208 | H8: =F8+G8 -> 1208 | J8: 2013 | K8: =B140 -> 3870 | L8: =C140 -> 95 | M8: =D140 -> 36959 | O8: =K8+L8 -> 3965 | P8: =M8 -> 36959 | Q8: =O8+P8 -> 40924
A9: 2014 | B9: 0 | C9: 0 | D9: 1190.85 | F9: =B9+C9 -> 0 | G9: =D9 -> 1190.85 | H9: =F9+G9 -> 1190.85 | J9: 2014 | K9: =B141 -> 3700.084 | L9: =C141 -> 109.169 | M9: =D141 -> 35057.115 | O9: =K9+L9 -> 3809.253 | P9: =M9 -> 35057.115 | Q9: =O9+P9 -> 38866.368
A10: 2015 | B10: 0 | C10: 0 | D10: 982.694 | F10: =B10+C10 -> 0 | G10: =D10 -> 982.694 | H10: =F10+G10 -> 982.694 | J10: 2015 | K10: =B142 -> 3152.212 | L10: =C142 -> 133.737 | M10: =D142 -> 19084.181 | O10: =K10+L10 -> 3285.949 | P10: =M10 -> 19084.181 | Q10: =O10+P10 -> 22370.13
A11: 2016 | B11: 0 | C11: 0 | D11: 999.26 | F11: =B11+C11 -> 0 | G11: =D11 -> 999.26 | H11: =F11+G11 -> 999.26 | J11: 2016 | K11: =B143 -> 3012.639 | L11: =C143 -> 103.188 | M11: =D143 -> 28811.863 | O11: =K11+L11 -> 3115.827 | P11: =M11 -> 28811.863 | Q11: =O11+P11 -> 31927.69
A12: 2017 | B12: 0 | C12: 0 | D12: 1453.933 | F12: =B12+C12 -> 0 | G12: =D12 -> 1453.933 | H12: =F12+G12 -> 1453.933 | J12: 2017 | K12: =B144 -> 3182.106 | L12: =C144 -> 128.115 | M12: =D144 -> 35534.237 | O12: =K12+L12 -> 3310.221 | P12: =M12 -> 35534.237 | Q12: =O12+P12 -> 38844.458
A13: 2018 | B13: 0 | C13: 0 | D13: 1413 | F13: =B13+C13 -> 0 | G13: =D13 -> 1413 | H13: =F13+G13 -> 1413 | J13: 2018 | K13: =B145 -> 3251 | L13: =C145 -> 133 | M13: =D145 -> 46503 | O13: =K13+L13 -> 3384 | P13: =M13 -> 46503 | Q13: =O13+P13 -> 49887
A14: 2019 | B14: 0 | C14: 0 | D14: 1211.534 | F14: =B14+C14 -> 0 | G14: =D14 -> 1211.534 | H14: =F14+G14 -> 1211.534 | J14: 2019 | K14: =B146 -> 2966.387 | L14: =C146 -> 100.974 | M14: =D146 -> 38876.223 | O14: =K14+L14 -> 3067.361 | P14: =M14 -> 38876.223 | Q14: =O14+P14 -> 41943.584
... A18: 2023 | B18: 0 | C18: 9.124 | D18: 1939.241 | F18: =B18+C18 -> 9.124 | G18: =D18 -> 1939.241 | H18: =F18+G18 -> 1948.365 | J18: 2023 | K18: =B150 -> 3000.968 | L18: =C150 -> 123.727 | M18: =D150 -> 38396.579 | O18: =K18+L18 -> 3124.695 | P18: =M18 -> 38396.579 | Q18: =O18+P18 -> 41521.274
A24: Bexar | J24: SAN ANTONIO POOL
A25: 2008 | B25: 244622 | C25: 19231 | D25: 7265 | F25: =B25+C25 -> 263853 | G25: =D25 -> 7265 | H25: =F25+G25 -> 271118 | J25: 2008 | K25: =B3+B25+B47+B69+B91+B113 -> 261887 | L25: =C3+C25+C47+C69+C91+C113 -> 28689 | M25: =D3+D25+D47+D69+D91+D113 -> 48993 | O25: =K25+L25 -> 290576 | P25: =M25 -> 48993 | Q25: =O25+P25 -> 339569
A26: 2009 | B26: 221633 | C26: 16766 | D26: 10233 | F26: =B26+C26 -> 238399 | G26: =D26 -> 10233 | H26: =F26+G26 -> 248632 | J26: 2009 | K26: =B4+B26+B48+B70+B92+B114 -> 238246 | L26: =C4+C26+C48+C70+C92+C114 -> 25219 | M26: =D4+D26+D48+D70+D92+D114 -> 50072 | O26: =K26+L26 -> 263465 | P26: =M26 -> 50072 | Q26: =O26+P26 -> 313537
A27: 2010 | B27: 236185 | C27: 17882 | D27: 5107 | F27: =B27+C27 -> 254067 | G27: =D27 -> 5107 | H27: =F27+G27 -> 259174 | J27: 2010 | K27: =B5+B27+B49+B71+B93+B115 -> 251229 | L27: =C5+C27+C49+C71+C93+C115 -> 26068 | M27: =D5+D27+D49+D71+D93+D115 -> 34572 | O27: =K27+L27 -> 277297 | P27: =M27 -> 34572 | Q27: =O27+P27 -> 311869
A28: 2011 | B28: 237620 | C28: 15269 | D28: 7436 | F28: =B28+C28 -> 252889 | G28: =D28 -> 7436 | H28: =F28+G28 -> 260325 | J28: 2011 | K28: =B6+B28+B50+B72+B94+B116 -> 255469 | L28: =C6+C28+C50+C72+C94+C116 -> 23241 | M28: =D6+D28+D50+D72+D94+D116 -> 56734 | O28: =K28+L28 -> 278710 | P28: =M28 -> 56734 | Q28: =O28+P28 -> 335444
A29: 2012 | B29: 237954 | C29: 14165 | D29: 4703 | F29: =B29+C29 -> 252119 | G29: =D29 -> 4703 | H29: =F29+G29 -> 256822 | J29: 2012 | K29: =B7+B29+B51+B73+B95+B117 -> 253522 | L29: =C7+C29+C51+C73+C95+C117 -> 22417 | M29: =D7+D29+D51+D73+D95+D117 -> 41393 | O29: =K29+L29 -> 275939 | P29: =M29 -> 41393 | Q29: =O29+P29 -> 317332
A30: 2013 | B30: 216051 | C30: 15648 | D30: 4179 | F30: =B30+C30 -> 231699 | G30: =D30 -> 4179 | H30: =F30+G30 -> 235878 | J30: 2013 | K30: =B8+B30+B52+B74+B96+B118 -> 230153 | L30: =C8+C30+C52+C74+C96+C118 -> 26175 | M30: =D8+D30+D52+D74+D96+D118 -> 39382 | O30: =K30+L30 -> 256328 | P30: =M30 -> 39382 | Q30: =O30+P30 -> 295710
A31: 2014 | B31: 196735.18 | C31: 13848.176 | D31: 4742.905 | F31: =B31+C31 -> 210583.36 | G31: =D31 -> 4742.905 | H31: =F31+G31 -> 215326.26 | J31: 2014 | K31: =B9+B31+B53+B75+B97+B119 -> 211114.8 | L31: =C9+C31+C53+C75+C97+C119 -> 22736.187 | M31: =D9+D31+D53+D75+D97+D119 -> 40231.253 | O31: =K31+L31 -> 233850.99 | P31: =M31 -> 40231.253 | Q31: =O31+P31 -> 274082.24
A32: 2015 | B32: 223553.63 | C32: 13929.399 | D32: 2809.539 | F32: =B32+C32 -> 237483.03 | G32: =D32 -> 2809.539 | H32: =F32+G32 -> 240292.57 | J32: 2015 | K32: =B10+B32+B54+B76+B98+B120 -> 238706.37 | L32: =C10+C32+C54+C76+C98+C120 -> 21753.105 | M32: =D10+D32+D54+D76+D98+D120 -> 22677.752 | O32: =K32+L32 -> 260459.48 | P32: =M32 -> 22677.752 | Q32: =O32+P32 -> 283137.23
A33: 2016 | B33: 207531.7 | C33: 14596.284 | D33: 3133.679 | F33: =B33+C33 -> 222127.98 | G33: =D33 -> 3133.679 | H33: =F33+G33 -> 225261.66 | J33: 2016 | K33: =B11+B33+B55+B77+B99+B121 -> 224235.94 | L33: =C11+C33+C55+C77+C99+C121 -> 23973.299 | M33: =D11+D33+D55+D77+D99+D121 -> 25857.167 | O33: =K33+L33 -> 248209.24 | P33: =M33 -> 25857.167 | Q33: =O33+P33 -> 274066.4
A34: 2017 | B34: 244528.14 | C34: 14947.588 | D34: 4951.192 | F34: =B34+C34 -> 259475.72 | G34: =D34 -> 4951.192 | H34: =F34+G34 -> 264426.92 | J34: 2017 | K34: =B12+B34+B56+B78+B100+B122 -> 259755.18 | L34: =C12+C34+C56+C78+C100+C122 -> 22667.108 | M34: =D12+D34+D56+D78+D100+D122 -> 38585.229 | O34: =K34+L34 -> 282422.28 | P34: =M34 -> 38585.229 | Q34: =O34+P34 -> 321007.51
A35: 2018 | B35: 223761 | C35: 15173 | D35: 4483 | F35: =B35+C35 -> 238934 | G35: =D35 -> 4483 | H35: =F35+G35 -> 243417 | J35: 2018 | K35: =B13+B35+B57+B79+B101+B123 -> 241841 | L35: =C13+C35+C57+C79+C101+C123 -> 21965 | M35: =D13+D35+D57+D79+D101+D123 -> 37447 | O35: =K35+L35 -> 263806 | P35: =M35 -> 37447 | Q35: =O35+P35 -> 301253
A36: 2019 | B36: 218856.24 | C36: 14365.623 | D36: 4350.187 | F36: =B36+C36 -> 233221.86 | G36: =D36 -> 4350.187 | H36: =F36+G36 -> 237572.05 | J36: 2019 | K36: =B14+B36+B58+B80+B102+B124 -> 238522.56 | L36: =C14+C36+C58+C80+C102+C124 -> 23701.612 | M36: =D14+D36+D58+D80+D102+D124 -> 34851.875 | O36: =K36+L36 -> 262224.18 | P36: =M36 -> 34851.875 | Q36: =O36+P36 -> 297076.05
... A40: 2023 | B40: 184180.51 | C40: 14527.774 | D40: 3410.541 | F40: =B40+C40 -> 198708.28 | G40: =D40 -> 3410.541 | H40: =F40+G40 -> 202118.82 | J40: 2023 | K40: =B18+B40+B62+B84+B106+B128 -> 203606.12 | L40: =C18+C40+C62+C84+C106+C128 -> 23490.782 | M40: =D18+D40+D62+D84+D106+D128 -> 31368.401 | O40: =K40+L40 -> 227096.91 | P40: =M40 -> 31368.401 | Q40: =O40+P40 -> 258465.31
A46: Comal | J46: GRAND TOTAL
A47: 2008 | B47: 6463 | C47: 6563 | D47: 61 | F47: =B47+C47 -> 13026 | G47: =D47 -> 61 | H47: =F47+G47 -> 13087 | J47: 2008 | K47: =K3+K25 -> 266655 | L47: =L3+L25 -> 28815 | M47: =M3+M25 -> 112708 | O47: =O3+O25 -> 295470 | P47: =P3+P25 -> 112708 | Q47: =O47+P47 -> 408178
A48: 2009 | B48: 6620 | C48: 5409 | D48: 65 | F48: =B48+C48 -> 12029 | G48: =D48 -> 65 | H48: =F48+G48 -> 12094 | J48: 2009 | K48: =K4+K26 -> 243043 | L48: =L4+L26 -> 25326 | M48: =M4+M26 -> 108886 | O48: =O4+O26 -> 268369 | P48: =P4+P26 -> 108886 | Q48: =O48+P48 -> 377255
A49: 2010 | B49: 5782 | C49: 5486 | D49: 33 | F49: =B49+C49 -> 11268 | G49: =D49 -> 33 | H49: =F49+G49 -> 11301 | J49: 2010 | K49: =K5+K27 -> 255204 | L49: =L5+L27 -> 26187 | M49: =M5+M27 -> 72690 | O49: =O5+O27 -> 281391 | P49: =P5+P27 -> 72690 | Q49: =O49+P49 -> 354081
A50: 2011 | B50: 7880 | C50: 4296 | D50: 72 | F50: =B50+C50 -> 12176 | G50: =D50 -> 72 | H50: =F50+G50 -> 12248 | J50: 2011 | K50: =K6+K28 -> 260331 | L50: =L6+L28 -> 23392 | M50: =M6+M28 -> 124905 | O50: =O6+O28 -> 283723 | P50: =P6+P28 -> 124905 | Q50: =O50+P50 -> 408628
A51: 2012 | B51: 6235 | C51: 4849 | D51: 78 | F51: =B51+C51 -> 11084 | G51: =D51 -> 78 | H51: =F51+G51 -> 11162 | J51: 2012 | K51: =K7+K29 -> 257877 | L51: =L7+L29 -> 22560 | M51: =M7+M29 -> 90556 | O51: =O7+O29 -> 280437 | P51: =P7+P29 -> 90556 | Q51: =O51+P51 -> 370993
A52: 2013 | B52: 5781 | C52: 7061 | D52: 63 | F52: =B52+C52 -> 12842 | G52: =D52 -> 63 | H52: =F52+G52 -> 12905 | J52: 2013 | K52: =K8+K30 -> 234023 | L52: =L8+L30 -> 26270 | M52: =M8+M30 -> 76341 | O52: =O8+O30 -> 260293 | P52: =P8+P30 -> 76341 | Q52: =O52+P52 -> 336634
A53: 2014 | B53: 5757.955 | C53: 5495.679 | D53: 63.415 | F53: =B53+C53 -> 11253.634 | G53: =D53 -> 63.415 | H53: =F53+G53 -> 11317.049 | J53: 2014 | K53: =K9+K31 -> 214814.89 | L53: =L9+L31 -> 22845.356 | M53: =M9+M31 -> 75288.368 | O53: =O9+O31 -> 237660.24 | P53: =P9+P31 -> 75288.368 | Q53: =O53+P53 -> 312948.61
A54: 2015 | B54: 6146.092 | C54: 4472.122 | D54: 43.829 | F54: =B54+C54 -> 10618.214 | G54: =D54 -> 43.829 | H54: =F54+G54 -> 10662.043 | J54: 2015 | K54: =K10+K32 -> 241858.58 | L54: =L10+L32 -> 21886.842 | M54: =M10+M32 -> 41761.933 | O54: =O10+O32 -> 263745.43 | P54: =P10+P32 -> 41761.933 | Q54: =O54+P54 -> 305507.36
A55: 2016 | B55: 6305.175 | C55: 4024.541 | D55: 46.461 | F55: =B55+C55 -> 10329.716 | G55: =D55 -> 46.461 | H55: =F55+G55 -> 10376.177 | J55: 2016 | K55: =K11+K33 -> 227248.58 | L55: =L11+L33 -> 24076.487 | M55: =M11+M33 -> 54669.03 | O55: =O11+O33 -> 251325.06 | P55: =P11+P33 -> 54669.03 | Q55: =O55+P55 -> 305994.09
A56: 2017 | B56: 4991.259 | C56: 2815.852 | D56: 41.518 | F56: =B56+C56 -> 7807.111 | G56: =D56 -> 41.518 | H56: =F56+G56 -> 7848.629 | J56: 2017 | K56: =K12+K34 -> 262937.28 | L56: =L12+L34 -> 22795.223 | M56: =M12+M34 -> 74119.466 | O56: =O12+O34 -> 285732.51 | P56: =P12+P34 -> 74119.466 | Q56: =O56+P56 -> 359851.97
...

Sheet Recharge
B2: Edwards Aquifer TEN-YEAR Rolling Recharge Average
B3: Calculator
B5: Year | C5: Recharge (AF) | D5: Ten-Year Average
B6: 2003 | C6: 669000
B7: 2004 | C7: 2176100 | E7: =AVERAGE(C6:C26) -> 634057.14
B8: 2005 | C8: 764000
B9: 2006 | C9: 201600
B10: 2007 | C10: 2162300
B11: 2008 | C11: 212900
B12: 2009 | C12: 211000
B13: 2010 | C13: 813500
B14: 2011 | C14: 112000
B15: 2012 | C15: 313500
B16: 2013 | C16: 182700 | D16: =AVERAGE(C7:C16) -> 714960
B17: 2014 | C17: 107200 | D17: =AVERAGE(C8:C17) -> 508070
B18: 2015 | C18: 1358300 | D18: =AVERAGE(C9:C18) -> 567500
B19: 2016 | C19: 1221100 | D19: =AVERAGE(C10:C19) -> 669450
B20: 2017 | C20: 487000 | D20: =AVERAGE(C11:C20) -> 501920
B21: 2018 | C21: 1100000 | D21: =AVERAGE(C12:C21) -> 590630
B22: 2019 | C22: 492000 | D22: =AVERAGE(C13:C22) -> 618730
B23: 2020 | C23: 184000 | D23: =AVERAGE(C14:C23) -> 555780
B24: 2021 | C24: 244000 | D24: =AVERAGE(C15:C24) -> 568980
B25: 2022 | C25: 156000 | D25: =AVERAGE(C16:C25) -> 553230
B26: 2023 | C26: 147000 | D26: =AVERAGE(C17:C26) -> 549660 | E26: : Current
B27: 2024 | C27: 635000 | D27: =AVERAGE(C18:C27) -> 602440
B28: 2025 | C28: 635000 | D28: =AVERAGE(C19:C28) -> 530110
B29: 2026 | C29: 635000 | D29: =AVERAGE(C20:C29) -> 471500
B30: 2027 | C30: 635000 | D30: =AVERAGE(C21:C30) -> 486300
B34: DOR if Ten-Year Average is less than 500,000 (AF).
B36: Drought of Record Forbearance Period (DORFP)
B37: During a DOR, the 10-day average of J-17 is less than 630 feet (msl).
